Workbook

Sheet ROM_Principale
A1: Opcode HEX | B1: Opcode DEC | C1: Instruction | D1: Actif | E1: RegWrite | F1: RegDst | G1: ALUSrc | H1: MemRead | I1: MemWrite | J1: MemToReg | K1: Branch | L1: Jump | M1: BranchNot | N1: ALUOp HEX | O1: ALUOp DEC | P1: ExtOp | Q1: jal | R1: LUI | S1: Valeur ROM HEX | T1: Valeur ROM DEC
A2: =DEC2HEX(B2,2) | B2: 0 | C2: R-type | D2: Oui | E2: 1 | F2: 1 | G2: 0 | H2: 0 | I2: 0 | J2: 0 | K2: 0 | L2: 0 | M2: 0 | N2: =DEC2HEX(O2,2) | O2: 2 | P2: 0 | Q2: 0 | R2: 0 | S2: =DEC2HEX(T2,4) | T2: =IF(D2="Oui",E2*1+F2*2+G2*4+H2*8+I2*16+J2*32+K2*64+L2*128+M2*256+O2*512+P2*2048+Q2*4096+R2*8192,0)
A3: =DEC2HEX(B3,2) | B3: 2 | C3: j | D3: Oui | E3: 0 | F3: 0 | G3: 0 | H3: 0 | I3: 0 | J3: 0 | K3: 0 | L3: 1 | M3: 0 | N3: =DEC2HEX(O3,2) | O3: 0 | P3: 0 | Q3: 0 | R3: 0 | S3: =DEC2HEX(T3,4) | T3: =IF(D3="Oui",E3*1+F3*2+G3*4+H3*8+I3*16+J3*32+K3*64+L3*128+M3*256+O3*512+P3*2048+Q3*4096+R3*8192,0)
A4: =DEC2HEX(B4,2) | B4: 3 | C4: jal | D4: Oui | E4: 1 | F4: 0 | G4: 0 | H4: 0 | I4: 0 | J4: 0 | K4: 0 | L4: 1 | M4: 0 | N4: =DEC2HEX(O4,2) | O4: 0 | P4: 0 | Q4: 1 | R4: 0 | S4: =DEC2HEX(T4,4) | T4: =IF(D4="Oui",E4*1+F4*2+G4*4+H4*8+I4*16+J4*32+K4*64+L4*128+M4*256+O4*512+P4*2048+Q4*4096+R4*8192,0)
A5: =DEC2HEX(B5,2) | B5: 4 | C5: beq | D5: Oui | E5: 0 | F5: 0 | G5: 0 | H5: 0 | I5: 0 | J5: 0 | K5: 1 | L5: 0 | M5: 0 | N5: =DEC2HEX(O5,2) | O5: 1 | P5: 0 | Q5: 0 | R5: 0 | S5: =DEC2HEX(T5,4) | T5: =IF(D5="Oui",E5*1+F5*2+G5*4+H5*8+I5*16+J5*32+K5*64+L5*128+M5*256+O5*512+P5*2048+Q5*4096+R5*8192,0)
A6: =DEC2HEX(B6,2) | B6: 5 | C6: bne | D6: Oui | E6: 0 | F6: 0 | G6: 0 | H6: 0 | I6: 0 | J6: 0 | K6: 0 | L6: 0 | M6: 1 | N6: =DEC2HEX(O6,2) | O6: 1 | P6: 0 | Q6: 0 | R6: 0 | S6: =DEC2HEX(T6,4) | T6: =IF(D6="Oui",E6*1+F6*2+G6*4+H6*8+I6*16+J6*32+K6*64+L6*128+M6*256+O6*512+P6*2048+Q6*4096+R6*8192,0)
A7: =DEC2HEX(B7,2) | B7: 8 | C7: addi | D7: Oui | E7: 1 | F7: 0 | G7: 1 | H7: 0 | I7: 0 | J7: 0 | K7: 0 | L7: 0 | M7: 0 | N7: =DEC2HEX(O7,2) | O7: 0 | P7: 1 | Q7: 0 | R7: 0 | S7: =DEC2HEX(T7,4) | T7: =IF(D7="Oui",E7*1+F7*2+G7*4+H7*8+I7*16+J7*32+K7*64+L7*128+M7*256+O7*512+P7*2048+Q7*4096+R7*8192,0)
A8: =DEC2HEX(B8,2) | B8: 13 | C8: ori | D8: Oui | E8: 1 | F8: 0 | G8: 1 | H8: 0 | I8: 0 | J8: 0 | K8: 0 | L8: 0 | M8: 0 | N8: =DEC2HEX(O8,2) | O8: 3 | P8: 0 | Q8: 0 | R8: 0 | S8: =DEC2HEX(T8,4) | T8: =IF(D8="Oui",E8*1+F8*2+G8*4+H8*8+I8*16+J8*32+K8*64+L8*128+M8*256+O8*512+P8*2048+Q8*4096+R8*8192,0)
A9: =DEC2HEX(B9,2) | B9: 15 | C9: lui | D9: Oui | E9: 1 | F9: 0 | G9: 0 | H9: 0 | I9: 0 | J9: 0 | K9: 0 | L9: 0 | M9: 0 | N9: =DEC2HEX(O9,2) | O9: 0 | P9: 0 | Q9: 0 | R9: 1 | S9: =DEC2HEX(T9,4) | T9: =IF(D9="Oui",E9*1+F9*2+G9*4+H9*8+I9*16+J9*32+K9*64+L9*128+M9*256+O9*512+P9*2048+Q9*4096+R9*8192,0)
A10: =DEC2HEX(B10,2) | B10: 35 | C10: lw | D10: Oui | E10: 1 | F10: 0 | G10: 1 | H10: 1 | I10: 0 | J10: 1 | K10: 0 | L10: 0 | M10: 0 | N10: =DEC2HEX(O10,2) | O10: 0 | P10: 1 | Q10: 0 | R10: 0 | S10: =DEC2HEX(T10,4) | T10: =IF(D10="Oui",E10*1+F10*2+G10*4+H10*8+I10*16+J10*32+K10*64+L10*128+M10*256+O10*512+P10*2048+Q10*4096+R10*8192,0)
A11: =DEC2HEX(B11,2) | B11: 43 | C11: sw | D11: Oui | E11: 0 | F11: 0 | G11: 1 | H11: 0 | I11: 1 | J11: 0 | K11: 0 | L11: 0 | M11: 0 | N11: =DEC2HEX(O11,2) | O11: 0 | P11: 1 | Q11: 0 | R11: 0 | S11: =DEC2HEX(T11,4) | T11: =IF(D11="Oui",E11*1+F11*2+G11*4+H11*8+I11*16+J11*32+K11*64+L11*128+M11*256+O11*512+P11*2048+Q11*4096+R11*8192,0)

Sheet ROM_ALUControl
A1: Funct HEX | B1: Funct DEC | C1: Instruction | D1: Actif | E1: AInvert | F1: BNegate | G1: OPR HEX | H1: OPR DEC | I1: JR | J1: Valeur HEX | K1: Valeur DEC
A2: =DEC2HEX(B2,2) | B2: 0 | C2: sll | D2: Oui | E2: 0 | F2: 0 | G2: =DEC2HEX(H2,2) | H2: 0 | I2: 0 | J2: =DEC2HEX(K2,2) | K2: =IF(D2="Oui",E2*16+F2*2+H2*4+I2,0)
A3: =DEC2HEX(B3,2) | B3: 2 | C3: srl | D3: Oui | E3: 0 | F3: 0 | G3: =DEC2HEX(H3,2) | H3: 1 | I3: 0 | J3: =DEC2HEX(K3,2) | K3: =IF(D3="Oui",E3*16+F3*2+H3*4+I3,0)
A4: =DEC2HEX(B4,2) | B4: 8 | C4: jr | D4: Oui | E4: 0 | F4: 0 | G4: =DEC2HEX(H4,2) | H4: 0 | I4: 1 | J4: =DEC2HEX(K4,2) | K4: =IF(D4="Oui",E4*16+F4*2+H4*4+I4,0)
A5: =DEC2HEX(B5,2) | B5: 32 | C5: add | D5: Oui | E5: 0 | F5: 0 | G5: =DEC2HEX(H5,2) | H5: 2 | I5: 0 | J5: =DEC2HEX(K5,2) | K5: =IF(D5="Oui",E5*16+F5*2+H5*4+I5,0)
A6: =DEC2HEX(B6,2) | B6: 34 | C6: sub | D6: Oui | E6: 0 | F6: 1 | G6: =DEC2HEX(H6,2) | H6: 2 | I6: 0 | J6: =DEC2HEX(K6,2) | K6: =IF(D6="Oui",E6*16+F6*2+H6*4+I6,0)
A7: =DEC2HEX(B7,2) | B7: 36 | C7: and | D7: Oui | E7: 0 | F7: 0 | G7: =DEC2HEX(H7,2) | H7: 0 | I7: 0 | J7: =DEC2HEX(K7,2) | K7: =IF(D7="Oui",E7*16+F7*2+H7*4+I7,0)
A8: =DEC2HEX(B8,2) | B8: 37 | C8: or | D8: Oui | E8: 0 | F8: 0 | G8: =DEC2HEX(H8,2) | H8: 1 | I8: 0 | J8: =DEC2HEX(K8,2) | K8: =IF(D8="Oui",E8*16+F8*2+H8*4+I8,0)
A9: =DEC2HEX(B9,2) | B9: 42 | C9: slt | D9: Oui | E9: 0 | F9: 1 | G9: =DEC2HEX(H9,2) | H9: 3 | I9: 0 | J9: =DEC2HEX(K9,2) | K9: =IF(D9="Oui",E9*16+F9*2+H9*4+I9,0)

Sheet Map_ROM_Principale
A1: Adresse DEC | B1: Adresse HEX | C1: Valeur HEX
A2: 0 | B2: =DEC2HEX(A2,2) | C2: =IFERROR(INDEX(ROM_Principale!$S$2:$S$64,MATCH(A2,ROM_Principale!$B$2:$B$64,0)),"0000")
A3: 1 | B3: =DEC2HEX(A3,2) | C3: =IFERROR(INDEX(ROM_Principale!$S$2:$S$64,MATCH(A3,ROM_Principale!$B$2:$B$64,0)),"0000")
A4: 2 | B4: =DEC2HEX(A4,2) | C4: =IFERROR(INDEX(ROM_Principale!$S$2:$S$64,MATCH(A4,ROM_Principale!$B$2:$B$64,0)),"0000")
A5: 3 | B5: =DEC2HEX(A5,2) | C5: =IFERROR(INDEX(ROM_Principale!$S$2:$S$64,MATCH(A5,ROM_Principale!$B$2:$B$64,0)),"0000")
A6: 4 | B6: =DEC2HEX(A6,2) | C6: =IFERROR(INDEX(ROM_Principale!$S$2:$S$64,MATCH(A6,ROM_Principale!$B$2:$B$64,0)),"0000")
A7: 5 | B7: =DEC2HEX(A7,2) | C7: =IFERROR(INDEX(ROM_Principale!$S$2:$S$64,MATCH(A7,ROM_Principale!$B$2:$B$64,0)),"0000")
A8: 6 | B8: =DEC2HEX(A8,2) | C8: =IFERROR(INDEX(ROM_Principale!$S$2:$S$64,MATCH(A8,ROM_Principale!$B$2:$B$64,0)),"0000")
A9: 7 | B9: =DEC2HEX(A9,2) | C9: =IFERROR(INDEX(ROM_Principale!$S$2:$S$64,MATCH(A9,ROM_Principale!$B$2:$B$64,0)),"0000")
A10: 8 | B10: =DEC2HEX(A10,2) | C10: =IFERROR(INDEX(ROM_Principale!$S$2:$S$64,MATCH(A10,ROM_Principale!$B$2:$B$64,0)),"0000")
A11: 9 | B11: =DEC2HEX(A11,2) | C11: =IFERROR(INDEX(ROM_Principale!$S$2:$S$64,MATCH(A11,ROM_Principale!$B$2:$B$64,0)),"0000")
A12: 10 | B12: =DEC2HEX(A12,2) | C12: =IFERROR(INDEX(ROM_Principale!$S$2:$S$64,MATCH(A12,ROM_Principale!$B$2:$B$64,0)),"0000")
A13: 11 | B13: =DEC2HEX(A13,2) | C13: =IFERROR(INDEX(ROM_Principale!$S$2:$S$64,MATCH(A13,ROM_Principale!$B$2:$B$64,0)),"0000")
... A65: 63 | B65: =DEC2HEX(A65,2) | C65: =IFERROR(INDEX(ROM_Principale!$S$2:$S$64,MATCH(A65,ROM_Principale!$B$2:$B$64,0)),"0000")

Sheet Map_ALUControl
A1: Adresse DEC | B1: Adresse HEX | C1: ALUOp DEC | D1: Funct DEC | E1: Valeur HEX
A2: 0 | B2: =DEC2HEX(A2,2) | C2: =INT(A2/64) | D2: =MOD(A2,64) | E2: =IF(AND(D2=8,OR(C2=1,C2=2)),IFERROR(INDEX(ROM_ALUControl!$J$2:$J$20,MATCH(D2,ROM_ALUControl!$B$2:$B$20,0)),"00"),IF(C2=0,"08",IF(C2=1,"0a",IF(C2=3,"04",IFERROR(INDEX(ROM_ALUControl!$J$2:$J$20,MATCH(D2,ROM_ALUControl!$B$2:$B$20,0)),"00")))))
A3: 1 | B3: =DEC2HEX(A3,2) | C3: =INT(A3/64) | D3: =MOD(A3,64) | E3: =IF(AND(D3=8,OR(C3=1,C3=2)),IFERROR(INDEX(ROM_ALUControl!$J$2:$J$20,MATCH(D3,ROM_ALUControl!$B$2:$B$20,0)),"00"),IF(C3=0,"08",IF(C3=1,"0a",IF(C3=3,"04",IFERROR(INDEX(ROM_ALUControl!$J$2:$J$20,MATCH(D3,ROM_ALUControl!$B$2:$B$20,0)),"00")))))
A4: 2 | B4: =DEC2HEX(A4,2) | C4: =INT(A4/64) | D4: =MOD(A4,64) | E4: =IF(AND(D4=8,OR(C4=1,C4=2)),IFERROR(INDEX(ROM_ALUControl!$J$2:$J$20,MATCH(D4,ROM_ALUControl!$B$2:$B$20,0)),"00"),IF(C4=0,"08",IF(C4=1,"0a",IF(C4=3,"04",IFERROR(INDEX(ROM_ALUControl!$J$2:$J$20,MATCH(D4,ROM_ALUControl!$B$2:$B$20,0)),"00")))))
A5: 3 | B5: =DEC2HEX(A5,2) | C5: =INT(A5/64) | D5: =MOD(A5,64) | E5: =IF(AND(D5=8,OR(C5=1,C5=2)),IFERROR(INDEX(ROM_ALUControl!$J$2:$J$20,MATCH(D5,ROM_ALUControl!$B$2:$B$20,0)),"00"),IF(C5=0,"08",IF(C5=1,"0a",IF(C5=3,"04",IFERROR(INDEX(ROM_ALUControl!$J$2:$J$20,MATCH(D5,ROM_ALUControl!$B$2:$B$20,0)),"00")))))
A6: 4 | B6: =DEC2HEX(A6,2) | C6: =INT(A6/64) | D6: =MOD(A6,64) | E6: =IF(AND(D6=8,OR(C6=1,C6=2)),IFERROR(INDEX(ROM_ALUControl!$J$2:$J$20,MATCH(D6,ROM_ALUControl!$B$2:$B$20,0)),"00"),IF(C6=0,"08",IF(C6=1,"0a",IF(C6=3,"04",IFERROR(INDEX(ROM_ALUControl!$J$2:$J$20,MATCH(D6,ROM_ALUControl!$B$2:$B$20,0)),"00")))))
A7: 5 | B7: =DEC2HEX(A7,2) | C7: =INT(A7/64) | D7: =MOD(A7,64) | E7: =IF(AND(D7=8,OR(C7=1,C7=2)),IFERROR(INDEX(ROM_ALUControl!$J$2:$J$20,MATCH(D7,ROM_ALUControl!$B$2:$B$20,0)),"00"),IF(C7=0,"08",IF(C7=1,"0a",IF(C7=3,"04",IFERROR(INDEX(ROM_ALUControl!$J$2:$J$20,MATCH(D7,ROM_ALUControl!$B$2:$B$20,0)),"00")))))
A8: 6 | B8: =DEC2HEX(A8,2) | C8: =INT(A8/64) | D8: =MOD(A8,64) | E8: =IF(AND(D8=8,OR(C8=1,C8=2)),IFERROR(INDEX(ROM_ALUControl!$J$2:$J$20,MATCH(D8,ROM_ALUControl!$B$2:$B$20,0)),"00"),IF(C8=0,"08",IF(C8=1,"0a",IF(C8=3,"04",IFERROR(INDEX(ROM_ALUControl!$J$2:$J$20,MATCH(D8,ROM_ALUControl!$B$2:$B$20,0)),"00")))))
A9: 7 | B9: =DEC2HEX(A9,2) | C9: =INT(A9/64) | D9: =MOD(A9,64) | E9: =IF(AND(D9=8,OR(C9=1,C9=2)),IFERROR(INDEX(ROM_ALUControl!$J$2:$J$20,MATCH(D9,ROM_ALUControl!$B$2:$B$20,0)),"00"),IF(C9=0,"08",IF(C9=1,"0a",IF(C9=3,"04",IFERROR(INDEX(ROM_ALUControl!$J$2:$J$20,MATCH(D9,ROM_ALUControl!$B$2:$B$20,0)),"00")))))
A10: 8 | B10: =DEC2HEX(A10,2) | C10: =INT(A10/64) | D10: =MOD(A10,64) | E10: =IF(AND(D10=8,OR(C10=1,C10=2)),IFERROR(INDEX(ROM_ALUControl!$J$2:$J$20,MATCH(D10,ROM_ALUControl!$B$2:$B$20,0)),"00"),IF(C10=0,"08",IF(C10=1,"0a",IF(C10=3,"04",IFERROR(INDEX(ROM_ALUControl!$J$2:$J$20,MATCH(D10,ROM_ALUControl!$B$2:$B$20,0)),"00")))))
A11: 9 | B11: =DEC2HEX(A11,2) | C11: =INT(A11/64) | D11: =MOD(A11,64) | E11: =IF(AND(D11=8,OR(C11=1,C11=2)),IFERROR(INDEX(ROM_ALUControl!$J$2:$J$20,MATCH(D11,ROM_ALUControl!$B$2:$B$20,0)),"00"),IF(C11=0,"08",IF(C11=1,"0a",IF(C11=3,"04",IFERROR(INDEX(ROM_ALUControl!$J$2:$J$20,MATCH(D11,ROM_ALUControl!$B$2:$B$20,0)),"00")))))
A12: 10 | B12: =DEC2HEX(A12,2) | C12: =INT(A12/64) | D12: =MOD(A12,64) | E12: =IF(AND(D12=8,OR(C12=1,C12=2)),IFERROR(INDEX(ROM_ALUControl!$J$2:$J$20,MATCH(D12,ROM_ALUControl!$B$2:$B$20,0)),"00"),IF(C12=0,"08",IF(C12=1,"0a",IF(C12=3,"04",IFERROR(INDEX(ROM_ALUControl!$J$2:$J$20,MATCH(D12,ROM_ALUControl!$B$2:$B$20,0)),"00")))))
A13: 11 | B13: =DEC2HEX(A13,2) | C13: =INT(A13/64) | D13: =MOD(A13,64) | E13: =IF(AND(D13=8,OR(C13=1,C13=2)),IFERROR(INDEX(ROM_ALUControl!$J$2:$J$20,MATCH(D13,ROM_ALUControl!$B$2:$B$20,0)),"00"),IF(C13=0,"08",IF(C13=1,"0a",IF(C13=3,"04",IFERROR(INDEX(ROM_ALUControl!$J$2:$J$20,MATCH(D13,ROM_ALUControl!$B$2:$B$20,0)),"00")))))
... A257: 255 | B257: =DEC2HEX(A257,2) | C257: =INT(A257/64) | D257: =MOD(A257,64) | E257: =IF(AND(D257=8,OR(C257=1,C257=2)),IFERROR(INDEX(ROM_ALUControl!$J$2:$J$20,MATCH(D257,ROM_ALUControl!$B$2:$B$20,0)),"00"),IF(C257=0,"08",IF(C257=1,"0a",IF(C257=3,"04",IFERROR(INDEX(ROM_ALUControl!$J$2:$J$20,MATCH(D257,ROM_ALUControl!$B$2:$B$20,0)),"00")))))

Sheet Textes_a_coller
A1: ROM principale 64 x 14 - cellule A2 ? copier
A2: ="v2.0 raw"&CHAR(10)&A3&CHAR(10)&A4&CHAR(10)&A5&CHAR(10)&A6&CHAR(10)&A7&CHAR(10)&A8&CHAR(10)&A9&CHAR(10)&A10
A3: =Map_ROM_Principale!C2&" "&Map_ROM_Principale!C3&" "&Map_ROM_Principale!C4&" "&Map_ROM_Principale!C5&" "&Map_ROM_Principale!C6&" "&Map_ROM_Principale!C7&" "&Map_ROM_Principale!C8&" "&Map_ROM_Principale!C9
A4: =Map_ROM_Principale!C10&" "&Map_ROM_Principale!C11&" "&Map_ROM_Principale!C12&" "&Map_ROM_Principale!C13&" "&Map_ROM_Principale!C14&" "&Map_ROM_Principale!C15&" "&Map_ROM_Principale!C16&" "&Map_ROM_Principale!C17
A5: =Map_ROM_Principale!C18&" "&Map_ROM_Principale!C19&" "&Map_ROM_Principale!C20&" "&Map_ROM_Principale!C21&" "&Map_ROM_Principale!C22&" "&Map_ROM_Principale!C23&" "&Map_ROM_Principale!C24&" "&Map_ROM_Principale!C25
A6: =Map_ROM_Principale!C26&" "&Map_ROM_Principale!C27&" "&Map_ROM_Principale!C28&" "&Map_ROM_Principale!C29&" "&Map_ROM_Principale!C30&" "&Map_ROM_Principale!C31&" "&Map_ROM_Principale!C32&" "&Map_ROM_Principale!C33
A7: =Map_ROM_Principale!C34&" "&Map_ROM_Principale!C35&" "&Map_ROM_Principale!C36&" "&Map_ROM_Principale!C37&" "&Map_ROM_Principale!C38&" "&Map_ROM_Principale!C39&" "&Map_ROM_Principale!C40&" "&Map_ROM_Principale!C41
A8: =Map_ROM_Principale!C42&" "&Map_ROM_Principale!C43&" "&Map_ROM_Principale!C44&" "&Map_ROM_Principale!C45&" "&Map_ROM_Principale!C46&" "&Map_ROM_Principale!C47&" "&Map_ROM_Principale!C48&" "&Map_ROM_Principale!C49
A9: =Map_ROM_Principale!C50&" "&Map_ROM_Principale!C51&" "&Map_ROM_Principale!C52&" "&Map_ROM_Principale!C53&" "&Map_ROM_Principale!C54&" "&Map_ROM_Principale!C55&" "&Map_ROM_Principale!C56&" "&Map_ROM_Principale!C57
A10: =Map_ROM_Principale!C58&" "&Map_ROM_Principale!C59&" "&Map_ROM_Principale!C60&" "&Map_ROM_Principale!C61&" "&Map_ROM_Principale!C62&" "&Map_ROM_Principale!C63&" "&Map_ROM_Principale!C64&" "&Map_ROM_Principale!C65
A13: ROM ALUControl 256 x 5 - cellule A14 ? copier
A14: ="v2.0 raw"&CHAR(10)&A15&CHAR(10)&A16&CHAR(10)&A17&CHAR(10)&A18&CHAR(10)&A19&CHAR(10)&A20&CHAR(10)&A21&CHAR(10)&A22&CHAR(10)&A23&CHAR(10)&A24&CHAR(10)&A25&CHAR(10)&A26&CHAR(10)&A27&CHAR(10)&A28&CHAR(10)&A29&CHAR(10)&A30&CHAR(10)&A31&CHAR(10)&A32&CHAR(10)&A33&CHAR(10)&A34&CHAR(10)&A35&CHAR(10)&A36&CHAR(10)&A37&CHAR(10)&A38&CHAR(10)&A39&CHAR(10)&A40&CHAR(10)&A41&CHAR(10)&A42&CHAR(10)&A43&CHAR(10)&A44&CHAR(10)&A45&CHAR(10)&A46
A15: =Map_ALUControl!E2&" "&Map_ALUControl!E3&" "&Map_ALUControl!E4&" "&Map_ALUControl!E5&" "&Map_ALUControl!E6&" "&Map_ALUControl!E7&" "&Map_ALUControl!E8&" "&Map_ALUControl!E9
A16: =Map_ALUControl!E10&" "&Map_ALUControl!E11&" "&Map_ALUControl!E12&" "&Map_ALUControl!E13&" "&Map_ALUControl!E14&" "&Map_ALUControl!E15&" "&Map_ALUControl!E16&" "&Map_ALUControl!E17
A17: =Map_ALUControl!E18&" "&Map_ALUControl!E19&" "&Map_ALUControl!E20&" "&Map_ALUControl!E21&" "&Map_ALUControl!E22&" "&Map_ALUControl!E23&" "&Map_ALUControl!E24&" "&Map_ALUControl!E25
A18: =Map_ALUControl!E26&" "&Map_ALUControl!E27&" "&Map_ALUControl!E28&" "&Map_ALUControl!E29&" "&Map_ALUControl!E30&" "&Map_ALUControl!E31&" "&Map_ALUControl!E32&" "&Map_ALUControl!E33
A19: =Map_ALUControl!E34&" "&Map_ALUControl!E35&" "&Map_ALUControl!E36&" "&Map_ALUControl!E37&" "&Map_ALUControl!E38&" "&Map_ALUControl!E39&" "&Map_ALUControl!E40&" "&Map_ALUControl!E41
A20: =Map_ALUControl!E42&" "&Map_ALUControl!E43&" "&Map_ALUControl!E44&" "&Map_ALUControl!E45&" "&Map_ALUControl!E46&" "&Map_ALUControl!E47&" "&Map_ALUControl!E48&" "&Map_ALUControl!E49
A21: =Map_ALUControl!E50&" "&Map_ALUControl!E51&" "&Map_ALUControl!E52&" "&Map_ALUControl!E53&" "&Map_ALUControl!E54&" "&Map_ALUControl!E55&" "&Map_ALUControl!E56&" "&Map_ALUControl!E57
A22: =Map_ALUControl!E58&" "&Map_ALUControl!E59&" "&Map_ALUControl!E60&" "&Map_ALUControl!E61&" "&Map_ALUControl!E62&" "&Map_ALUControl!E63&" "&Map_ALUControl!E64&" "&Map_ALUControl!E65
A23: =Map_ALUControl!E66&" "&Map_ALUControl!E67&" "&Map_ALUControl!E68&" "&Map_ALUControl!E69&" "&Map_ALUControl!E70&" "&Map_ALUControl!E71&" "&Map_ALUControl!E72&" "&Map_ALUControl!E73
A24: =Map_ALUControl!E74&" "&Map_ALUControl!E75&" "&Map_ALUControl!E76&" "&Map_ALUControl!E77&" "&Map_ALUControl!E78&" "&Map_ALUControl!E79&" "&Map_ALUControl!E80&" "&Map_ALUControl!E81
A25: =Map_ALUControl!E82&" "&Map_ALUControl!E83&" "&Map_ALUControl!E84&" "&Map_ALUControl!E85&" "&Map_ALUControl!E86&" "&Map_ALUControl!E87&" "&Map_ALUControl!E88&" "&Map_ALUControl!E89
A26: =Map_ALUControl!E90&" "&Map_ALUControl!E91&" "&Map_ALUControl!E92&" "&Map_ALUControl!E93&" "&Map_ALUControl!E94&" "&Map_ALUControl!E95&" "&Map_ALUControl!E96&" "&Map_ALUControl!E97
A27: =Map_ALUControl!E98&" "&Map_ALUControl!E99&" "&Map_ALUControl!E100&" "&Map_ALUControl!E101&" "&Map_ALUControl!E102&" "&Map_ALUControl!E103&" "&Map_ALUControl!E104&" "&Map_ALUControl!E105
A28: =Map_ALUControl!E106&" "&Map_ALUControl!E107&" "&Map_ALUControl!E108&" "&Map_ALUControl!E109&" "&Map_ALUControl!E110&" "&Map_ALUControl!E111&" "&Map_ALUControl!E112&" "&Map_ALUControl!E113
A29: =Map_ALUControl!E114&" "&Map_ALUControl!E115&" "&Map_ALUControl!E116&" "&Map_ALUControl!E117&" "&Map_ALUControl!E118&" "&Map_ALUControl!E119&" "&Map_ALUControl!E120&" "&Map_ALUControl!E121
A30: =Map_ALUControl!E122&" "&Map_ALUControl!E123&" "&Map_ALUControl!E124&" "&Map_ALUControl!E125&" "&Map_ALUControl!E126&" "&Map_ALUControl!E127&" "&Map_ALUControl!E128&" "&Map_ALUControl!E129
A31: =Map_ALUControl!E130&" "&Map_ALUControl!E131&" "&Map_ALUControl!E132&" "&Map_ALUControl!E133&" "&Map_ALUControl!E134&" "&Map_ALUControl!E135&" "&Map_ALUControl!E136&" "&Map_ALUControl!E137
A32: =Map_ALUControl!E138&" "&Map_ALUControl!E139&" "&Map_ALUControl!E140&" "&Map_ALUControl!E141&" "&Map_ALUControl!E142&" "&Map_ALUControl!E143&" "&Map_ALUControl!E144&" "&Map_ALUControl!E145
A33: =Map_ALUControl!E146&" "&Map_ALUControl!E147&" "&Map_ALUControl!E148&" "&Map_ALUControl!E149&" "&Map_ALUControl!E150&" "&Map_ALUControl!E151&" "&Map_ALUControl!E152&" "&Map_ALUControl!E153
A34: =Map_ALUControl!E154&" "&Map_ALUControl!E155&" "&Map_ALUControl!E156&" "&Map_ALUControl!E157&" "&Map_ALUControl!E158&" "&Map_ALUControl!E159&" "&Map_ALUControl!E160&" "&Map_ALUControl!E161
A35: =Map_ALUControl!E162&" "&Map_ALUControl!E163&" "&Map_ALUControl!E164&" "&Map_ALUControl!E165&" "&Map_ALUControl!E166&" "&Map_ALUControl!E167&" "&Map_ALUControl!E168&" "&Map_ALUControl!E169
A36: =Map_ALUControl!E170&" "&Map_ALUControl!E171&" "&Map_ALUControl!E172&" "&Map_ALUControl!E173&" "&Map_ALUControl!E174&" "&Map_ALUControl!E175&" "&Map_ALUControl!E176&" "&Map_ALUControl!E177
A37: =Map_ALUControl!E178&" "&Map_ALUControl!E179&" "&Map_ALUControl!E180&" "&Map_ALUControl!E181&" "&Map_ALUControl!E182&" "&Map_ALUControl!E183&" "&Map_ALUControl!E184&" "&Map_ALUControl!E185
A38: =Map_ALUControl!E186&" "&Map_ALUControl!E187&" "&Map_ALUControl!E188&" "&Map_ALUControl!E189&" "&Map_ALUControl!E190&" "&Map_ALUControl!E191&" "&Map_ALUControl!E192&" "&Map_ALUControl!E193
A39: =Map_ALUControl!E194&" "&Map_ALUControl!E195&" "&Map_ALUControl!E196&" "&Map_ALUControl!E197&" "&Map_ALUControl!E198&" "&Map_ALUControl!E199&" "&Map_ALUControl!E200&" "&Map_ALUControl!E201
A40: =Map_ALUControl!E202&" "&Map_ALUControl!E203&" "&Map_ALUControl!E204&" "&Map_ALUControl!E205&" "&Map_ALUControl!E206&" "&Map_ALUControl!E207&" "&Map_ALUControl!E208&" "&Map_ALUControl!E209
A41: =Map_ALUControl!E210&" "&Map_ALUControl!E211&" "&Map_ALUControl!E212&" "&Map_ALUControl!E213&" "&Map_ALUControl!E214&" "&Map_ALUControl!E215&" "&Map_ALUControl!E216&" "&Map_ALUControl!E217
A42: =Map_ALUControl!E218&" "&Map_ALUControl!E219&" "&Map_ALUControl!E220&" "&Map_ALUControl!E221&" "&Map_ALUControl!E222&" "&Map_ALUControl!E223&" "&Map_ALUControl!E224&" "&Map_ALUControl!E225
...

Sheet Aide
A1: Classeur r?par? - formules dynamiques
A2: ? copier : Textes_a_coller!A2 pour la ROM principale.
A3: ? copier : Textes_a_coller!A14 pour la ROM ALUControl.
A4: Les lignes d aide sont masqu?es : elles servent seulement ? garder des formules courtes et compatibles.
A5: Les colonnes DEC sont num?riques; les colonnes HEX sont g?n?r?es avec DEC2HEX.
